<?xml version="1.0"?>
<robot name="physics">
    <link name="slideBar">
    <visual>
      <geometry>
        <box size="15 0.025 0.025"/>
      </geometry>
      <origin xyz="0 0 0"/>
      <material name="orange">
        <color rgba="1 0.5 .1 1"/>
      </material>
    </visual>
    <inertial>
      <mass value="0"/>
      <inertia ixx="1.0" ixy="0" ixz="0.0" iyy="1.0" iyz="0.0" izz="1.0"/>
    </inertial>
  </link>

  
    <link name="body">
    <visual>
      <geometry>
        <box size="0.6 0.5 0.1"/>
      </geometry>
      <origin xyz="0 0 0"/>
      <material name="green">
        <color rgba="0 1 0 1"/>
      </material>
    </visual>
    <collision>
      <geometry>
        <box size="0.6 0.5 0.1"/>
      </geometry>
      <origin xyz="0 0 0"/>
    </collision>
    <inertial>
      <mass value="10"/>
      <inertia ixx="1.0" ixy="0.0" ixz="0.0" iyy="1.0" iyz="0.0" izz="1.0"/>
    </inertial>
  </link>

   <link name="FTSensor">
    <visual>
      <geometry>
        <cylinder radius="0.05" length="0.05"/>
      </geometry>
      <origin xyz="0 0 0"/>
      <material name="blue">
        <color rgba="0 0 1 1"/>
      </material>
    </visual>
  </link>






    <link name="link1">
    <visual>
      <geometry>      
             <box size="0.05 0.05 0.25"/>
      </geometry>
      <origin xyz="0 0.0 0.125"/>
      <material name="gray">
        <color rgba="0.5 0.5 0.5 1"/>
      </material>
    </visual>
      <collision>
      <geometry>
             <box size="0.05 0.05 0.25"/>
      </geometry>
      <origin xyz="0 0 0.125"/>
    </collision>
    <inertial>
         <origin xyz="0 0 0.125"/>
      <mass value="0"/>
      <inertia ixx="1.0" ixy="0.0" ixz="0.0" iyy="1.0" iyz="0.0" izz="1.0"/>
    </inertial>
    </link>
    

    <link name="link2">
    <visual>
      <geometry>      
             <box size="0.05 0.05 0.5"/>
      </geometry>
      <origin xyz="0 0.0 0.25"/>
      <material name="whitegray">
        <color rgba="0.8 0.8 0.8 1"/>
      </material>
    </visual>
      <collision>
      <geometry>
             <box size="0.05 0.05 0.5"/>
      </geometry>
      <origin xyz="0 0 0.25"/>
    </collision>
    <inertial>
      <mass value="2"/>
     <origin xyz="0 0 0.25"/>
      <inertia ixx="1.0" ixy="0.0" ixz="0.0" iyy="1.0" iyz="0.0" izz="1.0"/>
    </inertial>
    </link>
      
  
      <link name="link3">
    <visual>
      <geometry>      
             <box size="0.05 0.05 0.5"/>
      </geometry>
      <origin xyz="0 0.0 0.25"/>
      <material name="gray2">
        <color rgba="0.5 0.5 0.5 1"/>
      </material>
    </visual>
      <collision>
      <geometry>
             <box size="0.05 0.05 0.5"/>
      </geometry>
      <origin xyz="0 0 0.25"/>
    </collision>
    <inertial>
      <mass value="2"/>
     <origin xyz="0 0 0.25"/>
      <inertia ixx="1.0" ixy="0.0" ixz="0.0" iyy="1.0" iyz="0.0" izz="1.0"/>
    </inertial>
    </link>

  
  <link name="EEF">
    <visual>
      <geometry>
        <cylinder radius="0.05" length="0.05"/>
      </geometry>
      <origin xyz="0 0 0"/>
      <material name="red">
        <color rgba="1 0 0 1"/>
      </material>
    </visual>
  </link>
    <joint name="slider_to_cart" type="prismatic">
    <axis xyz="1 0 0"/>
    <origin xyz="0.0 0.0 0.1"/>
    <parent link="slideBar"/>
    <child link="body"/>
    <limit effort="1000.0" lower="-7.5" upper="7.5" velocity="5"/>
  </joint>
  
  <joint name="body_to_FTseneor" type="fixed">
    <axis xyz="0 0 1"/>
    <origin xyz="0.2 0 0.05" rpy="0 0 0"/>
    <parent link="body"/>
    <child link="FTSensor"/>
    
  </joint>

  <joint name="joint1" type="fixed">
    <axis xyz="0 1 0"/>
    <origin xyz="0.0 0 0.0" rpy="0 0 0"/>
    <parent link="FTSensor"/>
    <child link="link1"/>
    
  </joint>

      <joint name="joint2" type="continuous">
    <axis xyz="0 1 0"/>
    <origin xyz="0.0 0.0 0.25" rpy="0 0 0"/>
    <parent link="link1"/>
    <child link="link2"/>
  </joint>
  
      <joint name="joint3" type="continuous">
    <axis xyz="0 1 0"/>
    <origin xyz="0.0 0.0 0.5" rpy="0 0 0"/>
    <parent link="link2"/>
    <child link="link3"/>
  </joint>
  
     <joint name="eef_joint" type="fixed">
    <axis xyz="0 1 0"/>
    <origin xyz="0.0 0.0 0.5" rpy="0 0 0"/>
    <parent link="link3"/>
    <child link="EEF"/>
  </joint>

</robot>
